Workbook

Sheet Summary
A1: Brand | B1: 2025 Total (Aug-Sep) | C1: 2026 Total (Aug-Sep, confirmed)
A2: HAV | B2: 122 | C2: 67
A3: CZ | B3: 80 | C3: 44
A4: ID | B4: 82 | C4: 83
A5: BUR | B5: 87 | C5: 67
A6: STF | B6: 47 | C6: 25
A7: TI | B7: 52 | C7: 44

Sheet Data
A1: Brand | B1: Year | C1: Date | D1: Day | E1: Email Name | F1: Category | G1: Type | H1: Status | I1: Asana Link | J1: Week Offset (0 = Labor Day week)
A2: BUR | B2: 2025 | C2: 2025-08-01 | D2: Fri | E2: P_EM_2025_08_01_BW_D_Title_Highlight | F2: Non-Sale | G2: Designed | J2: -5
A3: BUR | B3: 2025 | C3: 2025-08-02 | D3: Sat | E3: P_EM_2025_08_02_BW_D_Copilot_Highlight | F3: Non-Sale | G3: Designed | J3: -5
A4: BUR | B4: 2025 | C4: 2025-08-02 | D4: Sat | E4: P_EM_2025_08_02_BW_D_Referral_Promo | F4: Non-Sale | G4: Designed | J4: -5
A5: BUR | B5: 2025 | C5: 2025-08-03 | D5: Sun | E5: P_EM_2025_08_03_BW_D_Accent_Seating_Highlight | F5: Non-Sale | G5: Designed | J5: -5
A6: BUR | B6: 2025 | C6: 2025-08-04 | D6: Mon | E6: P_EM_2025_08_04_BW_D_Modularity_Resend | F6: Non-Sale | G6: Designed | J6: -4
A7: BUR | B7: 2025 | C7: 2025-08-05 | D7: Tue | E7: P_EM_2025_08_05_BW_D_Airmail_Highlight | F7: Non-Sale | G7: Designed | J7: -4
A8: BUR | B8: 2025 | C8: 2025-08-05 | D8: Tue | E8: P_EM_2025_08_05_BW_PT_BOS_Tax_Free_Weekend | F8: Non-Sale | G8: Plain-Text | J8: -4
A9: BUR | B9: 2025 | C9: 2025-08-06 | D9: Wed | E9: P_EM_2025_08_06_BW_D_L_Fall_Preview_Launch | F9: Non-Sale | G9: Designed | J9: -4
A10: BUR | B10: 2025 | C10: 2025-08-07 | D10: Thu | E10: P_EM_2025_08_07_BW_D_L_Sunset_Sale_Launch | F10: Sunset Sale / Sunset Sale / Flash Sale | G10: Designed | J10: -4
A11: BUR | B11: 2025 | C11: 2025-08-08 | D11: Fri | E11: P_EM_2025_08_08_BW_D_Sunset_Sale_Reminder | F11: Sunset Sale / Sunset Sale / Flash Sale | G11: Designed | J11: -4
A12: BUR | B12: 2025 | C12: 2025-08-09 | D12: Sat | E12: P_EM_2025_08_09_BW_D_Leather_Highlight | F12: Sunset Sale / Sunset Sale / Flash Sale | G12: Designed | J12: -4
A13: BUR | B13: 2025 | C13: 2025-08-10 | D13: Sun | E13: P_EM_2025_08_10_BW_D_Quick_Ship | F13: Sunset Sale / Sunset Sale / Flash Sale | G13: Designed | J13: -4
... A88: BUR | B88: 2025 | C88: 2025-09-30 | D88: Tue | E88: P_EM_2025_09_30_BW_PT_Holiday_Ready_Sale_Last_Chance_PM | F88: Holiday-Ready Sale | G88: Plain-Text | J88: 4
A89: BUR | B89: 2026 | C89: 2026-08-01 | D89: Sat | E89: Free Swatches | F89: Non-Sale | G89: Plain-Text | H89: Launched | I89: https://app.asana.com/1/5257710284167/project/1207353785125835/task/1216366484350801 | J89: -6
A90: BUR | B90: 2026 | C90: 2026-08-02 | D90: Sun | E90: Outdoor Feature | F90: Non-Sale | G90: Batch & Blast | H90: Launched | I90: https://app.asana.com/1/5257710284167/project/1207353785125835/task/1216366245190808 | J90: -6
A91: BUR | B91: 2026 | C91: 2026-08-03 | D91: Mon | E91: Nomad Collection | F91: Non-Sale | G91: Batch & Blast | H91: Launched | I91: https://app.asana.com/1/5257710284167/project/1207353785125835/task/1216366095057202 | J91: -5
A92: BUR | B92: 2026 | C92: 2026-08-04 | D92: Tue | E92: Storage Feature | F92: Non-Sale | G92: Plain-Text | H92: Launched | I92: https://app.asana.com/1/5257710284167/project/1207353785125835/task/1216366245398095 | J92: -5
A93: BUR | B93: 2026 | C93: 2026-08-06 | D93: Thu | E93: Sunset Sale Launch | F93: Flash Sale | G93: Batch & Blast | H93: Launched | I93: https://app.asana.com/1/5257710284167/project/1207353785125835/task/1216366037458114 | J93: -5
A94: BUR | B94: 2026 | C94: 2026-08-07 | D94: Fri | E94: Sunset Sale — Sectionals | F94: Flash Sale | G94: Batch & Blast | H94: Launched | I94: https://app.asana.com/1/5257710284167/project/1207353785125835/task/1216366266234560 | J94: -5
A95: BUR | B95: 2026 | C95: 2026-08-08 | D95: Sat | E95: Sunset Sale — Bedroom | F95: Flash Sale | G95: Plain-Text | H95: Launched | I95: https://app.asana.com/1/5257710284167/project/1207353785125835/task/1216366266342201 | J95: -5
A96: BUR | B96: 2026 | C96: 2026-08-09 | D96: Sun | E96: Sunset Sale — Outdoor | F96: Flash Sale | G96: Batch & Blast | H96: Launched | I96: https://app.asana.com/1/5257710284167/project/1207353785125835/task/1216366484352027 | J96: -5
A97: BUR | B97: 2026 | C97: 2026-08-10 | D97: Mon | E97: Sunset Sale — Dining | F97: Flash Sale | G97: Batch & Blast | H97: Launched | I97: https://app.asana.com/1/5257710284167/project/1207353785125835/task/1216366266349632 | J97: -4
A98: BUR | B98: 2026 | C98: 2026-08-11 | D98: Tue | E98: Sunset Sale — Quick Ship | F98: Flash Sale | G98: Plain-Text | H98: Launched | I98: https://app.asana.com/1/5257710284167/project/1207353785125835/task/1216366244706796 | J98: -4
A99: BUR | B99: 2026 | C99: 2026-08-12 | D99: Wed | E99: Sunset Sale Final Hours — Evening | F99: Flash Sale | G99: Plain-Text | H99: Launched | I99: https://app.asana.com/1/5257710284167/project/1207353785125835/task/1216366037363474 | J99: -4
A100: BUR | B100: 2026 | C100: 2026-08-12 | D100: Wed | E100: Sunset Sale Final Hours — Morning | F100: Flash Sale | G100: Batch & Blast | H100: Launched | I100: https://app.asana.com/1/5257710284167/project/1207353785125835/task/1216366201051150 | J100: -4
... A155: BUR | B155: 2026 | C155: 2026-09-28 | D155: Mon | E155: Reminder (PT, PM) | F155: Autumn Event | G155: Plain-Text | H155: Ready for QA | I155: https://app.asana.com/1/5257710284167/project/1207522423363072/task/1217036093534522 | J155: 3
A156: CZ | B156: 2025 | C156: 2025-08-02 | D156: Sat | E156: P_EM_2025_08_02_CZ_D_PR_Neutral_Rugs_Edit | F156: Non-Sale | G156: Designed | J156: -5
A157: CZ | B157: 2025 | C157: 2025-08-03 | D157: Sun | E157: P_EM_2025_08_03_CZ_D_PR_Back_In_Stock | F157: Non-Sale | G157: Designed | J157: -5
A158: CZ | B158: 2025 | C158: 2025-08-03 | D158: Sun | E158: P_EM_2025_08_03_HAV_CONV_D_Rug_Event_CZ_Rug_Spotlight | F158: Non-Sale | G158: Designed | J158: -5
A159: CZ | B159: 2025 | C159: 2025-08-04 | D159: Mon | E159: P_EM_2025_08_04_CZ_D_PR_Morrocan_Restock | F159: Non-Sale | G159: Designed | J159: -4
A160: CZ | B160: 2025 | C160: 2025-08-06 | D160: Wed | E160: P_EM_2025_08_06_CZ_D_PR_Fall_Preview | F160: Non-Sale | G160: Designed | J160: -4
A161: CZ | B161: 2025 | C161: 2025-08-07 | D161: Thu | E161: P_EM_2025_08_07_CZ_D_PR_Sunset_Sale | F161: Sunset Sale / Sunset Sale / Flash Sale | G161: Designed | J161: -4
A162: CZ | B162: 2025 | C162: 2025-08-07 | D162: Thu | E162: SEG_EM_2025_08_07_CZ_D_Review_Sweepstakes_Announcement | F162: Sunset Sale / Sunset Sale / Flash Sale | G162: Designed | J162: -4
A163: CZ | B163: 2025 | C163: 2025-08-08 | D163: Fri | E163: P_EM_2025_08_08_CZ_D_PR_Sunset_Sale_Categories | F163: Sunset Sale / Sunset Sale / Flash Sale | G163: Designed | J163: -4
A164: CZ | B164: 2025 | C164: 2025-08-09 | D164: Sat | E164: P_EM_2025_08_09_CZ_D_PR_Well_Traveled_Home | F164: Sunset Sale / Sunset Sale / Flash Sale | G164: Designed | J164: -4
A165: CZ | B165: 2025 | C165: 2025-08-09 | D165: Sat | E165: P_EM_2025_08_09_CZ_PT_Archive_Sale_Reminder | F165: Sunset Sale / Sunset Sale / Flash Sale | G165: Plain-Text | J165: -4
A166: CZ | B166: 2025 | C166: 2025-08-10 | D166: Sun | E166: P_EM_2025_08_10_CZ_D_PR_Artful_Accents | F166: Sunset Sale / Sunset Sale / Flash Sale | G166: Designed | J166: -4
A167: CZ | B167: 2025 | C167: 2025-08-11 | D167: Mon | E167: P_EM_2025_08_11_CZ_D_PR_Archive_Sale | F167: Sunset Sale / Sunset Sale / Flash Sale | G167: Designed | J167: -3
... A235: CZ | B235: 2025 | C235: 2025-09-30 | D235: Tue | E235: P_EM_2025_09_30_PT_CZ_Weekender_Sale_Last_Chance_PM | F235: Weekender Sale / Weekender Flash Sale | G235: Plain-Text | J235: 4
...

Sheet Labor Day Window - Review
A1: ±1 week around Labor Day (day offset -7 to +6). 2025 names = actual Braze/Klaviyo campaign names (sent). 2026 names = Asana task names (planned). HAV combined "DPS and MP" tickets are split into 2 rows to match how 2025 counted each audience separately.
A3: HAV
A4: Year | B4: Date | C4: Day Offset | D4: Name | E4: Relevant to Labor Day? (Y/N)
A5: 2025 | B5: 2025-08-25 | C5: -7 | D5: P_EM_2025_08_25_HAV_CONV_D_Items_in_Your_Design_on_Sale
A6: 2025 | B6: 2025-08-25 | C6: -7 | D6: P_EM_2025_08_25_HAV_CONV_D_Vendor_Roundup
A7: 2025 | B7: 2025-08-25 | C7: -7 | D7: P_EM_2025_08_25_HAV_PC_Labor_Day_Event_Reminder_PT
A8: 2025 | B8: 2025-08-26 | C8: -6 | D8: P_EM_2025_08_26_HAV_CONV_D_Hideaway
A9: 2025 | B9: 2025-08-26 | C9: -6 | D9: P_EM_2025_08_26_HAV_PC_D_Hideaway
A10: 2025 | B10: 2025-08-27 | C10: -5 | D10: P_EM_2025_08_27_HAV_CONV_D_Items_in_Your_Design_on_Sweetner
A11: 2025 | B11: 2025-08-27 | C11: -5 | D11: P_EM_2025_08_27_HAV_CONV_D_L_Mid_Promo_Sweetener
A12: 2025 | B12: 2025-08-27 | C12: -5 | D12: P_EM_2025_08_27_HAV_PC_D_L_Mid_Promo_Sweetener
A13: 2025 | B13: 2025-08-28 | C13: -4 | D13: P_DM_2025_08_28_HAV_CONV_Mid_Promo_Reminder_PM_PT
A14: 2025 | B14: 2025-08-28 | C14: -4 | D14: P_EM_2025_08_28_HAV_CONV_D_Mid_Promo_Sweetener_Ends_Tonight
A15: 2025 | B15: 2025-08-29 | C15: -3 | D15: P_EM_2025_08_29_HAV_CONV_D_Labor_Day_Event_Final_Weekend
A16: 2025 | B16: 2025-08-29 | C16: -3 | D16: P_EM_2025_08_29_HAV_CONV_Labor_Day_Design_Check_In_PM_PT
... A64: 2026 | B64: 2026-09-13 | C64: 6 | D64: MP: Labor Day Extension Reminder
A67: CZ
A68: Year | B68: Date | C68: Day Offset | D68: Name | E68: Relevant to Labor Day? (Y/N)
A69: 2025 | B69: 2025-08-25 | C69: -7 | D69: P_2025_8_25_PM_CZ_Price_Drop_New_Email
A70: 2025 | B70: 2025-08-25 | C70: -7 | D70: P_EM_2025_08_25_CZ_D_PR_Labor_Day_Event_Sale_Categories
A71: 2025 | B71: 2025-08-26 | C71: -6 | D71: P_EM_2025_08_26_CZ_D_PR_Fall_Bedding
A72: 2025 | B72: 2025-08-26 | C72: -6 | D72: P_EM_2025_08_26_PT_CZ_Cart_Abandon_Labor_Day_Event_PM
A73: 2025 | B73: 2025-08-26 | C73: -6 | D73: P_EM_2025_08_26_PT_CZ_Swatchees_Labor_Day_Event_PM
A74: 2025 | B74: 2025-08-27 | C74: -5 | D74: P_EM_2025_08_27_CZ_D_PR_Stocked_Furniture_Highlight
A75: 2025 | B75: 2025-08-27 | C75: -5 | D75: P_EM_2025_08_27_PT_CZ_Fresh_Cuts_Archive_Sale_PM
A76: 2025 | B76: 2025-08-27 | C76: -5 | D76: P_EM_2025_08_27_PT_CZ_Retail_Email_PM
A77: 2025 | B77: 2025-08-28 | C77: -4 | D77: P_EM_2025_08_28_CZ_D_PR_Labor_Day_Event_Sale_Reminder
A78: 2025 | B78: 2025-08-28 | C78: -4 | D78: P_EM_2025_8_28_PM_CZ_Price_Drop_New_Email
A79: 2025 | B79: 2025-08-29 | C79: -3 | D79: P_EM_2025_08_29_CZ_D_PR_LDW_Sale_Sweetener
A80: 2025 | B80: 2025-08-30 | C80: -2 | D80: P_EM_2025_08_30_CZ_D_PR_Archive_Sale_PM
... A102: 2026 | B102: 2026-09-12 | C102: 5 | D102: Labor Day Event Ext Reminder
A105: ID
A106: Year | B106: Date | C106: Day Offset | D106: Name | E106: Relevant to Labor Day? (Y/N)
A107: 2025 | B107: 2025-08-25 | C107: -7 | D107: P_EM_2025_08_25_ID_D_Items_in_your_cart
A108: 2025 | B108: 2025-08-25 | C108: -7 | D108: P_EM_2025_08_25_ID_D_Labor_Day_Event_Reminder
A109: 2025 | B109: 2025-08-26 | C109: -6 | D109: P_EM_2025_08_26_ID_D_New_Arrivals
A110: 2025 | B110: 2025-08-26 | C110: -6 | D110: P_EM_2025_08_26_ID_PT_PM_Labor_Day_Reminder_Swatchees
A111: 2025 | B111: 2025-08-27 | C111: -5 | D111: P_EM_2025_08_27_ID_D_L_Dining_Highlight
A112: 2025 | B112: 2025-08-28 | C112: -4 | D112: P_EM_2025_08_28_ID_D_Labor_Day_Event_Reminder
A113: 2025 | B113: 2025-08-29 | C113: -3 | D113: P_EM_2025_08_29_ID_D_Friday_Retail
...

Sheet HAV
A1: HAV — 2025 (Aug 1 – Sep 30) | G1: HAV — 2026 (Aug 1 – Sep 30, planned)
A2: Date | B2: Day | C2: Email Name | D2: Category | E2: Type | G2: Date | H2: Day | I2: Email Name | J2: Category | K2: Type | L2: Status | M2: Asana Link
A3: 2025-08-01 | B3: Fri | C3: P_EM_2025_08_01_HAV_CONV_D_The_Rug_Event_Launch | D3: Rug Event | E3: Designed | G3: 2026-08-01 | H3: Sat | I3: DPS and MP: Designer-Approved Home Items (DPS) | J3: Non-Sale | K3: Batch & Blast | L3: Launched | M3: https://app.asana.com/1/5257710284167/project/1207522423363072/task/1216314372035481
A4: 2025-08-02 | B4: Sat | C4: P_EM_2025_08_02_HAV_CONV_D_Keltie_Knight_Home_Tour | D4: Rug Event | E4: Designed | G4: 2026-08-01 | H4: Sat | I4: DPS and MP: Designer-Approved Home Items (MP) | J4: Non-Sale | K4: Batch & Blast | L4: Launched | M4: https://app.asana.com/1/5257710284167/project/1207522423363072/task/1216314372035481
A5: 2025-08-02 | B5: Sat | C5: P_EM_2025_08_02_HAV_PC_D_Keltie_Knight_Home_Tour | D5: Rug Event | E5: Designed | G5: 2026-08-03 | H5: Mon | I5: DPS and MP: In and Out Trends (DPS) | J5: Non-Sale | K5: Batch & Blast | L5: Launched | M5: https://app.asana.com/1/5257710284167/project/1207522423363072/task/1216368555290164
A6: 2025-08-03 | B6: Sun | C6: P_EM_2025_08_03_HAV_PC_D_Before_Afters | D6: Rug Event | E6: Designed | G6: 2026-08-03 | H6: Mon | I6: DPS and MP: In and Out Trends (MP) | J6: Non-Sale | K6: Batch & Blast | L6: Launched | M6: https://app.asana.com/1/5257710284167/project/1207522423363072/task/1216368555290164
A7: 2025-08-04 | B7: Mon | C7: P_EM_2025_08_04_HAV_CONV_Rug_Event_Reminder_PM_PT | D7: Rug Event | E7: Plain-Text | G7: 2026-08-03 | H7: Mon | I7: Havenly Tipping Triggered Email | J7: Non-Sale | K7: Plain-Text | L7: Launched | M7: https://app.asana.com/1/5257710284167/project/1207522423363072/task/1216733832027017
A8: 2025-08-05 | B8: Tue | C8: P_EM_2025_08_05_HAV_CONV_D_Rug_Event_Ends_Tomorrow | D8: Rug Event | E8: Designed | G8: 2026-08-04 | H8: Tue | I8: DPS and MP: The 33 Most Timeless Green Paints, According to Designers (DPS) | J8: Non-Sale | K8: Batch & Blast | L8: Launched | M8: https://app.asana.com/1/5257710284167/project/1207522423363072/task/1216762920456494
A9: 2025-08-06 | B9: Wed | C9: P_EM_2025_08_06_HAV_CONV_D_Hideaway | D9: Rug Event | E9: Designed | G9: 2026-08-04 | H9: Tue | I9: DPS and MP: The 33 Most Timeless Green Paints, According to Designers (MP) | J9: Non-Sale | K9: Batch & Blast | L9: Launched | M9: https://app.asana.com/1/5257710284167/project/1207522423363072/task/1216762920456494
A10: 2025-08-06 | B10: Wed | C10: P_EM_2025_08_06_HAV_CONV_D_Rug_Event_Ending_Tonight | D10: Rug Event | E10: Designed | G10: 2026-08-06 | H10: Thu | I10: DPS: Labor Day Event Launch | J10: Flash Sale / Labor Day Event | K10: Batch & Blast | L10: Launched | M10: https://app.asana.com/1/5257710284167/project/1207522423363072/task/1216760250839191
A11: 2025-08-06 | B11: Wed | C11: P_EM_2025_08_06_HAV_PC_D_Hideaway | D11: Rug Event | E11: Designed | G11: 2026-08-06 | H11: Thu | I11: MP: Flash Sale Launch | J11: Flash Sale / Labor Day Event | K11: Batch & Blast | L11: Launched | M11: https://app.asana.com/1/5257710284167/project/1207522423363072/task/1216760250804618
A12: 2025-08-07 | B12: Thu | C12: P_EM_2025_08_07_HAV_CONV_D_Sunset_Sale_Launch | D12: Sunset Sale / Labor Day Event | E12: Designed | G12: 2026-08-07 | H12: Fri | I12: DPS: Labor Day Event Early Reminder | J12: Flash Sale / Labor Day Event | K12: Batch & Blast | L12: Launched | M12: https://app.asana.com/1/5257710284167/project/1207522423363072/task/1216967691643722
A13: 2025-08-07 | B13: Thu | C13: P_EM_2025_08_07_HAV_PC_D_L_Labor_Day_Event_Launch | D13: Sunset Sale / Labor Day Event | E13: Designed | G13: 2026-08-07 | H13: Fri | I13: MP: Flash Sale Early Reminder | J13: Flash Sale / Labor Day Event | K13: Batch & Blast | L13: Launched | M13: https://app.asana.com/1/5257710284167/project/1207522423363072/task/1216967691679714
... A69: 2025-09-04 | B69: Thu | C69: P_EM_2025_09_04_HAV_CONV_D_Hideaway | D69: Weekend Flash Sale | E69: Designed | G69: 2026-09-15 | H69: Tue | I69: MP: Labor Day Extension Last Chance | J69: Labor Day (Extension) / Labor Day Event (Extension) | K69: Batch & Blast | L69: Awaiting Creative | M69: https://app.asana.com/1/5257710284167/project/1207522423363072/task/1216759950649114
A70: 2025-09-04 | B70: Thu | C70: P_EM_2025_09_04_HAV_CONV_D_Tiered_Sale | D70: Weekend Flash Sale | E70: Designed
A71: 2025-09-04 | B71: Thu | C71: P_EM_2025_09_04_HAV_PC_D_Hideaway | D71: Weekend Flash Sale | E71: Designed
A72: 2025-09-05 | B72: Fri | C72: P_EM_2025_09_05_HAV_CONV_D_Tiered_Sale | D72: Weekend Flash Sale | E72: Designed
A73: 2025-09-06 | B73: Sat | C73: P_EM_2025_09_06_HAV_CONV_D_Warm_Transitional | D73: Weekend Flash Sale | E73: Designed
A74: 2025-09-06 | B74: Sat | C74: P_EM_2025_09_06_HAV_CONV_D_Warm_Transitional | D74: Weekend Flash Sale | E74: Designed
A75: 2025-09-06 | B75: Sat | C75: P_EM_2025_09_06_HAV_PC_Extension Reminder_PT | D75: Weekend Flash Sale | E75: Plain-Text
A76: 2025-09-07 | B76: Sun | C76: P_EM_2025_09_07_HAV_CONV_D_Flash_Sale_Ends_Tomorrow | D76: Weekend Flash Sale | E76: Designed
A77: 2025-09-07 | B77: Sun | C77: P_EM_2025_09_07_HAV_PC_D_Warm_Transitional | D77: Weekend Flash Sale | E77: Designed
A78: 2025-09-08 | B78: Mon | C78: P_EM_2025_09_08_HAV_CONV_D_Flash_Sale_Final_Hours | D78: Weekend Flash Sale | E78: Designed
A79: 2025-09-08 | B79: Mon | C79: P_EM_2025_09_08_HAV_CONV_Flash_Sale_Final_Hours_PT_PM | D79: Weekend Flash Sale | E79: Plain-Text
A80: 2025-09-09 | B80: Tue | C80: P_EM_2025_09_09_HAV_PC_D_Labor_Day_Event_Extension_Last_Chance | D80: Weekend Flash Sale | E80: Designed
A81: 2025-09-10 | B81: Wed | C81: P_EM_2025_09_10_HAV_CONV_D_Hideaway | D81: Private Sale | E81: Designed
... A124: 2025-09-30 | B124: Tue | C124: P_EM_2025_09_30_HAV_PC_D_Get_Guest_Ready_Sale_Last_Chance | D124: Holiday-Ready Sale | E124: Designed

Sheet CZ
A1: CZ — 2025 (Aug 1 – Sep 30) | G1: CZ — 2026 (Aug 1 – Sep 30, planned)
A2: Date | B2: Day | C2: Email Name | D2: Category | E2: Type | G2: Date | H2: Day | I2: Email Name | J2: Category | K2: Type | L2: Status | M2: Asana Link
A3: 2025-08-02 | B3: Sat | C3: P_EM_2025_08_02_CZ_D_PR_Neutral_Rugs_Edit | D3: Non-Sale | E3: Designed | G3: 2026-08-02 | H3: Sun | I3: Monthly Edit | J3: Non-Sale | K3: Batch & Blast | L3: Launched | M3: https://app.asana.com/1/5257710284167/project/1207353785125835/task/1216604390997367
A4: 2025-08-03 | B4: Sun | C4: P_EM_2025_08_03_CZ_D_PR_Back_In_Stock | D4: Non-Sale | E4: Designed | G4: 2026-08-04 | H4: Tue | I4: Bedding: Percale, Perfected | J4: Non-Sale | K4: Batch & Blast | L4: Launched | M4: https://app.asana.com/1/5257710284167/project/1207353785125835/task/1216604595988632
A5: 2025-08-03 | B5: Sun | C5: P_EM_2025_08_03_HAV_CONV_D_Rug_Event_CZ_Rug_Spotlight | D5: Non-Sale | E5: Designed | G5: 2026-08-06 | H5: Thu | I5: Flash Sale Launch | J5: Flash Sale | K5: Batch & Blast | L5: Launched | M5: https://app.asana.com/1/5257710284167/project/1207353785125835/task/1216604626952901
A6: 2025-08-04 | B6: Mon | C6: P_EM_2025_08_04_CZ_D_PR_Morrocan_Restock | D6: Non-Sale | E6: Designed | G6: 2026-08-07 | H6: Fri | I6: MTO Sofas: Artisan Story | J6: Flash Sale | K6: Batch & Blast | L6: Launched | M6: https://app.asana.com/1/5257710284167/project/1207353785125835/task/1216604685116397
A7: 2025-08-06 | B7: Wed | C7: P_EM_2025_08_06_CZ_D_PR_Fall_Preview | D7: Non-Sale | E7: Designed | G7: 2026-08-08 | H7: Sat | I7: Bedding: Linen, Layered, Loved | J7: Flash Sale | K7: Batch & Blast | L7: Launched | M7: https://app.asana.com/1/5257710284167/project/1207353785125835/task/1216605791841077
A8: 2025-08-07 | B8: Thu | C8: P_EM_2025_08_07_CZ_D_PR_Sunset_Sale | D8: Sunset Sale / Sunset Sale / Flash Sale | E8: Designed | G8: 2026-08-09 | H8: Sun | I8: Destination: Melides, Portugal | J8: Flash Sale | K8: Batch & Blast | L8: Launched | M8: https://app.asana.com/1/5257710284167/project/1207353785125835/task/1216605791779460
A9: 2025-08-07 | B9: Thu | C9: SEG_EM_2025_08_07_CZ_D_Review_Sweepstakes_Announcement | D9: Sunset Sale / Sunset Sale / Flash Sale | E9: Designed | G9: 2026-08-10 | H9: Mon | I9: Back in Stock | J9: Flash Sale | K9: Batch & Blast | L9: Launched | M9: https://app.asana.com/1/5257710284167/project/1207353785125835/task/1216605625542997
A10: 2025-08-08 | B10: Fri | C10: P_EM_2025_08_08_CZ_D_PR_Sunset_Sale_Categories | D10: Sunset Sale / Sunset Sale / Flash Sale | E10: Designed | G10: 2026-08-11 | H10: Tue | I10: Archive Sale | J10: Flash Sale | K10: Batch & Blast | L10: Launched | M10: https://app.asana.com/1/5257710284167/project/1207353785125835/task/1216605792611432
A11: 2025-08-09 | B11: Sat | C11: P_EM_2025_08_09_CZ_D_PR_Well_Traveled_Home | D11: Sunset Sale / Sunset Sale / Flash Sale | E11: Designed | G11: 2026-08-12 | H11: Wed | I11: Flash Sale Last Chance | J11: Flash Sale | K11: Batch & Blast | L11: Launched | M11: https://app.asana.com/1/5257710284167/project/1207353785125835/task/1216605937834211
A12: 2025-08-09 | B12: Sat | C12: P_EM_2025_08_09_CZ_PT_Archive_Sale_Reminder | D12: Sunset Sale / Sunset Sale / Flash Sale | E12: Plain-Text | G12: 2026-08-13 | H12: Thu | I12: MTO Furniture: Artful Silhouettes | J12: Non-Sale | K12: Batch & Blast | L12: Launched | M12: https://app.asana.com/1/5257710284167/project/1207353785125835/task/1216605792932201
A13: 2025-08-10 | B13: Sun | C13: P_EM_2025_08_10_CZ_D_PR_Artful_Accents | D13: Sunset Sale / Sunset Sale / Flash Sale | E13: Designed | G13: 2026-08-14 | H13: Fri | I13: Color Edit: Golden Hour | J13: Non-Sale | K13: Batch & Blast | L13: Launched | M13: https://app.asana.com/1/5257710284167/project/1207353785125835/task/1216605991882847
... A46: 2025-09-01 | B46: Mon | C46: P_EM_2025_09_01_CZ_D_PR_Labor_Day_Event_Sale_Reminder_AM | D46: Labor Day Event | E46: Designed | G46: 2026-09-30 | H46: Wed | I46: Flash Sale Last Chance | J46: Flash Sale | K46: Batch & Blast | L46: Awaiting Creative | M46: https://app.asana.com/1/5257710284167/project/1207353785125835/task/1217341769515113
A47: 2025-09-01 | B47: Mon | C47: P_EM_2025_09_01_CZ_D_PR_Labor_Day_Event_Sale_Reminder_PM | D47: Labor Day Event | E47: Designed
A48: 2025-09-02 | B48: Tue | C48: P_EM_2025_09_02_CZ_D_PR_Labor_Day_Last_Chance_AM | D48: Labor Day Event | E48: Designed
A49: 2025-09-02 | B49: Tue | C49: P_EM_2025_09_02_PT_CZ_Cart_Abandoners_Labor_Day_Event_Ends_Tonight_PM | D49: Labor Day Event | E49: Plain-Text
A50: 2025-09-02 | B50: Tue | C50: P_EM_2025_09_02_PT_CZ_Engaged_Labor_Day_Event_Ends_Tonight_PM | D50: Labor Day Event | E50: Plain-Text
A51: 2025-09-02 | B51: Tue | C51: P_EM_2025_09_02_PT_CZ_Swatchees_Labor_Day_Event_Ends_Tonight_PM | D51: Labor Day Event | E51: Plain-Text
A52: 2025-09-03 | B52: Wed | C52: P_EM_2025_09_03_CZ_D_PR_Labor_Day_Sale_Extension_Announcement | D52: Labor Day Event (Extension) | E52: Designed
A53: 2025-09-04 | B53: Thu | C53: P_EM_2025_09_04_CZ_D_PR_Spa_Escape | D53: Labor Day Event (Extension) | E53: Designed
A54: 2025-09-06 | B54: Sat | C54: P_EM_2025_09_06_PT_CZ_Morocco_Restock | D54: Labor Day Event (Extension) | E54: Plain-Text
A55: 2025-09-07 | B55: Sun | C55: P_EM_2025_09_07_CZ_D_PR_Fall_Foundations | D55: Labor Day Event (Extension) | E55: Designed
A56: 2025-09-08 | B56: Mon | C56: P_EM_2025_09_08_CZ_D_PR_Labor_Day_Sale_Extension_Last_Chance | D56: Labor Day Event (Extension) | E56: Designed
A57: 2025-09-10 | B57: Wed | C57: P_EM_2025_09_10_CZ_D_PR_Archive_Sale | D57: Non-Sale | E57: Designed
A58: 2025-09-11 | B58: Thu | C58: P_EM_2025_09_11_CZ_D_PR_Oaxaca_Collection | D58: Non-Sale | E58: Designed
... A82: 2025-09-30 | B82: Tue | C82: P_EM_2025_09_30_PT_CZ_Weekender_Sale_Last_Chance_PM | D82: Weekender Sale / Weekender Flash Sale | E82: Plain-Text

Sheet ID
A1: ID — 2025 (Aug 1 – Sep 30) | G1: ID — 2026 (Aug 1 – Sep 30, planned)
A2: Date | B2: Day | C2: Email Name | D2: Category | E2: Type | G2: Date | H2: Day | I2: Email Name | J2: Category | K2: Type | L2: Status | M2: Asana Link
A3: 2025-08-01 | B3: Fri | C3: P_EM_2025_08_01_ID_D_Friday_Retail | D3: Non-Sale | E3: Designed | G3: 2026-08-01 | H3: Sat | I3: Warehouse Sale Starts Today | J3: Warehouse Sale | K3: Designed | L3: Launched | M3: https://app.asana.com/1/5257710284167/project/1207522423363072/task/1216725835163005
A4: 2025-08-02 | B4: Sat | C4: P_EM_2025_08_02_ID_D_Shop_Bedroom_Kaleb_Bed | D4: Non-Sale | E4: Designed | G4: 2026-08-02 | H4: Sun | I4: Leather Sofas & Sectionals | J4: Warehouse Sale | K4: Plain-Text | L4: Launched | M4: https://app.asana.com/1/5257710284167/project/1207353785125835/task/1216316769869058
A5: 2025-08-03 | B5: Sun | C5: P_EM_2025_08_03_ID_D_CZ_Partner_Spotlight | D5: Non-Sale | E5: Designed | G5: 2026-08-03 | H5: Mon | I5: Warehouse Sale Reminder - PT | J5: Warehouse Sale | K5: Plain-Text | L5: QA Proof Sent | M5: https://app.asana.com/1/5257710284167/project/1207522423363072/task/1216725835163016
A6: 2025-08-04 | B6: Mon | C6: P_EM_2025_08_04_ID_D_New_Arrivals | D6: Non-Sale | E6: Designed | G6: 2026-08-04 | H6: Tue | I6: Swatch Talk: Greens | J6: Warehouse Sale | K6: Batch & Blast | L6: Launched | M6: https://app.asana.com/1/5257710284167/project/1207353785125835/task/1216316757378972
A7: 2025-08-05 | B7: Tue | C7: P_EM_2025_08_05_ID_D_Swatch_Talk_Blue_Hues_Open_Skies | D7: Non-Sale | E7: Designed | G7: 2026-08-05 | H7: Wed | I7: Final Day Warehouse Sale | J7: Warehouse Sale | K7: Designed | L7: Launched | M7: https://app.asana.com/1/5257710284167/project/1207522423363072/task/1216725835163024
A8: 2025-08-06 | B8: Wed | C8: P_EM_2025_08_06_ID_D_L_Fall_Preview_Launch | D8: Non-Sale | E8: Designed | G8: 2026-08-06 | H8: Thu | I8: Flash Sale Launch | J8: Flash Sale | K8: Batch & Blast | L8: Launched | M8: https://app.asana.com/1/5257710284167/project/1207353785125835/task/1216322104808131
A9: 2025-08-07 | B9: Thu | C9: P_EM_2025_08_07_ID_D_L_Sunset_Sale_Launch | D9: Sunset Sale / Sunset Sale / Flash Sale | E9: Designed | G9: 2026-08-07 | H9: Fri | I9: Flash Sale: Sofas/Sectionals Reminder | J9: Flash Sale | K9: Plain-Text | L9: Launched | M9: https://app.asana.com/1/5257710284167/project/1207353785125835/task/1216316757973624
A10: 2025-08-08 | B10: Fri | C10: P_EM_2025_08_08_ID_D_Sectional_Buying_Guide | D10: Sunset Sale / Sunset Sale / Flash Sale | E10: Designed | G10: 2026-08-07 | H10: Fri | I10: PM Send MA Tax Free - PT | J10: Flash Sale | K10: Plain-Text | L10: Ready for QA | M10: https://app.asana.com/1/5257710284167/project/1207522423363072/task/1217287984870978
A11: 2025-08-08 | B11: Fri | C11: P_EM_2025_08_08_ID_PT_Boston_Tax_Free | D11: Sunset Sale / Sunset Sale / Flash Sale | E11: Plain-Text | G11: 2026-08-08 | H11: Sat | I11: Flash Sale: Ella Collection Spotlight | J11: Flash Sale | K11: Batch & Blast | L11: QA Proof Sent | M11: https://app.asana.com/1/5257710284167/project/1207353785125835/task/1216338809773609
A12: 2025-08-09 | B12: Sat | C12: P_EM_2025_08_09_ID_D_Sunset_Sale_Reminder | D12: Sunset Sale / Sunset Sale / Flash Sale | E12: Designed | G12: 2026-08-09 | H12: Sun | I12: Swatch Talk: Pet Friendly Whites | J12: Flash Sale | K12: Batch & Blast | L12: Launched | M12: https://app.asana.com/1/5257710284167/project/1207353785125835/task/1216316771694361
A13: 2025-08-10 | B13: Sun | C13: P_EM_2025_08_10_ID_D_Collection_Spotlight_Sloan | D13: Sunset Sale / Sunset Sale / Flash Sale | E13: Designed | G13: 2026-08-10 | H13: Mon | I13: Flash Sale: James Collection Spotlight | J13: Flash Sale | K13: Batch & Blast | L13: Launched | M13: https://app.asana.com/1/5257710284167/project/1207353785125835/task/1216316757965285
... A84: 2025-09-30 | B84: Tue | C84: P_EM_2025_09_30_ID_PT_Holiday_Ready_Sale_Final_Hours_PM | D84: Holiday-Ready Sale | E84: Plain-Text | G84: 2026-09-30 | H84: Wed | I84: Final Hours (PM) | J84: Flash Sale | K84: Plain-Text | L84: Awaiting Creative | M84: https://app.asana.com/1/5257710284167/project/1207353785125835/task/1217033364806972
G85: 2026-09-30 | H85: Wed | I85: Flash Sale Last Chance | J85: Flash Sale | K85: Batch & Blast | L85: Awaiting Creative | M85: https://app.asana.com/1/5257710284167/project/1207353785125835/task/1217033530107885

Sheet BUR
A1: BUR — 2025 (Aug 1 – Sep 30) | G1: BUR — 2026 (Aug 1 – Sep 30, planned)
A2: Date | B2: Day | C2: Email Name | D2: Category | E2: Type | G2: Date | H2: Day | I2: Email Name | J2: Category | K2: Type | L2: Status | M2: Asana Link
A3: 2025-08-01 | B3: Fri | C3: P_EM_2025_08_01_BW_D_Title_Highlight | D3: Non-Sale | E3: Designed | G3: 2026-08-01 | H3: Sat | I3: Free Swatches | J3: Non-Sale | K3: Plain-Text | L3: Launched | M3: https://app.asana.com/1/5257710284167/project/1207353785125835/task/1216366484350801
A4: 2025-08-02 | B4: Sat | C4: P_EM_2025_08_02_BW_D_Copilot_Highlight | D4: Non-Sale | E4: Designed | G4: 2026-08-02 | H4: Sun | I4: Outdoor Feature | J4: Non-Sale | K4: Batch & Blast | L4: Launched | M4: https://app.asana.com/1/5257710284167/project/1207353785125835/task/1216366245190808
A5: 2025-08-02 | B5: Sat | C5: P_EM_2025_08_02_BW_D_Referral_Promo | D5: Non-Sale | E5: Designed | G5: 2026-08-03 | H5: Mon | I5: Nomad Collection | J5: Non-Sale | K5: Batch & Blast | L5: Launched | M5: https://app.asana.com/1/5257710284167/project/1207353785125835/task/1216366095057202
A6: 2025-08-03 | B6: Sun | C6: P_EM_2025_08_03_BW_D_Accent_Seating_Highlight | D6: Non-Sale | E6: Designed | G6: 2026-08-04 | H6: Tue | I6: Storage Feature | J6: Non-Sale | K6: Plain-Text | L6: Launched | M6: https://app.asana.com/1/5257710284167/project/1207353785125835/task/1216366245398095
A7: 2025-08-04 | B7: Mon | C7: P_EM_2025_08_04_BW_D_Modularity_Resend | D7: Non-Sale | E7: Designed | G7: 2026-08-06 | H7: Thu | I7: Sunset Sale Launch | J7: Flash Sale | K7: Batch & Blast | L7: Launched | M7: https://app.asana.com/1/5257710284167/project/1207353785125835/task/1216366037458114
A8: 2025-08-05 | B8: Tue | C8: P_EM_2025_08_05_BW_D_Airmail_Highlight | D8: Non-Sale | E8: Designed | G8: 2026-08-07 | H8: Fri | I8: Sunset Sale — Sectionals | J8: Flash Sale | K8: Batch & Blast | L8: Launched | M8: https://app.asana.com/1/5257710284167/project/1207353785125835/task/1216366266234560
A9: 2025-08-05 | B9: Tue | C9: P_EM_2025_08_05_BW_PT_BOS_Tax_Free_Weekend | D9: Non-Sale | E9: Plain-Text | G9: 2026-08-08 | H9: Sat | I9: Sunset Sale — Bedroom | J9: Flash Sale | K9: Plain-Text | L9: Launched | M9: https://app.asana.com/1/5257710284167/project/1207353785125835/task/1216366266342201
A10: 2025-08-06 | B10: Wed | C10: P_EM_2025_08_06_BW_D_L_Fall_Preview_Launch | D10: Non-Sale | E10: Designed | G10: 2026-08-09 | H10: Sun | I10: Sunset Sale — Outdoor | J10: Flash Sale | K10: Batch & Blast | L10: Launched | M10: https://app.asana.com/1/5257710284167/project/1207353785125835/task/1216366484352027
A11: 2025-08-07 | B11: Thu | C11: P_EM_2025_08_07_BW_D_L_Sunset_Sale_Launch | D11: Sunset Sale / Sunset Sale / Flash Sale | E11: Designed | G11: 2026-08-10 | H11: Mon | I11: Sunset Sale — Dining | J11: Flash Sale | K11: Batch & Blast | L11: Launched | M11: https://app.asana.com/1/5257710284167/project/1207353785125835/task/1216366266349632
A12: 2025-08-08 | B12: Fri | C12: P_EM_2025_08_08_BW_D_Sunset_Sale_Reminder | D12: Sunset Sale / Sunset Sale / Flash Sale | E12: Designed | G12: 2026-08-11 | H12: Tue | I12: Sunset Sale — Quick Ship | J12: Flash Sale | K12: Plain-Text | L12: Launched | M12: https://app.asana.com/1/5257710284167/project/1207353785125835/task/1216366244706796
A13: 2025-08-09 | B13: Sat | C13: P_EM_2025_08_09_BW_D_Leather_Highlight | D13: Sunset Sale / Sunset Sale / Flash Sale | E13: Designed | G13: 2026-08-12 | H13: Wed | I13: Sunset Sale Final Hours — Evening | J13: Flash Sale | K13: Plain-Text | L13: Launched | M13: https://app.asana.com/1/5257710284167/project/1207353785125835/task/1216366037363474
... A69: 2025-09-16 | B69: Tue | C69: P_EM_2025_09_16_BW_PT_PM_Subscriber_Flash_Sale_Reminder | D69: Subscriber Flash Sale - Lifecycle/Retail Only / VIP Flash Sale | E69: Plain-Text | G69: 2026-09-28 | H69: Mon | I69: Reminder (PT, PM) | J69: Autumn Event | K69: Plain-Text | L69: Ready for QA | M69: https://app.asana.com/1/5257710284167/project/1207522423363072/task/1217036093534522
A70: 2025-09-17 | B70: Wed | C70: P_EM_2025_09_17_BW_D_Holiday_Ready_Sale_Launch | D70: Holiday-Ready Sale | E70: Designed
A71: 2025-09-18 | B71: Thu | C71: P_EM_2025_09_18_BW_D_Back_to_School_Bestsellers | D71: Holiday-Ready Sale | E71: Designed
A72: 2025-09-19 | B72: Fri | C72: P_EM_2025_09_19_BW_D_Opera_Highlight | D72: Holiday-Ready Sale | E72: Designed
A73: 2025-09-20 | B73: Sat | C73: P_EM_2025_09_20_BW_D_Holiday_Ready_Sale_Reminder | D73: Holiday-Ready Sale | E73: Designed
A74: 2025-09-20 | B74: Sat | C74: P_EM_2025_09_20_BW_D_Sectional_Highlight | D74: Holiday-Ready Sale | E74: Designed
A75: 2025-09-21 | B75: Sun | C75: P_EM_2025_09_21_BW_D_Storage_Highlight | D75: Holiday-Ready Sale | E75: Designed
A76: 2025-09-22 | B76: Mon | C76: P_EM_2025_09_22_BW_D_Holiday_Ready_Sale_Reminder | D76: Holiday-Ready Sale | E76: Designed
A77: 2025-09-23 | B77: Tue | C77: P_EM_2025_09_23_BW_D_PM_Bestsellers | D77: Holiday-Ready Sale | E77: Designed
A78: 2025-09-23 | B78: Tue | C78: P_EM_2025_09_23_BW_PT_Holiday_Ready_Sale_Reminder | D78: Holiday-Ready Sale | E78: Plain-Text
A79: 2025-09-23 | B79: Tue | C79: P_EM_2025_09_23_BW_PT_Holiday_Ready_Sale_Reminder_Resend | D79: Holiday-Ready Sale | E79: Plain-Text
A80: 2025-09-24 | B80: Wed | C80: P_EM_2025_09_24_BW_D_Holiday_Ready_Sale_Reminder | D80: Holiday-Ready Sale | E80: Designed
A81: 2025-09-25 | B81: Thu | C81: P_EM_2025_09_25_BW_D_Best Seat_in_the_House | D81: Holiday-Ready Sale | E81: Designed
... A89: 2025-09-30 | B89: Tue | C89: P_EM_2025_09_30_BW_PT_Holiday_Ready_Sale_Last_Chance_PM | D89: Holiday-Ready Sale | E89: Plain-Text

Sheet STF
A1: STF — 2025 (Aug 1 – Sep 30) | G1: STF — 2026 (Aug 1 – Sep 30, planned)
A2: Date | B2: Day | C2: Email Name | D2: Category | E2: Type | G2: Date | H2: Day | I2: Email Name | J2: Category | K2: Type | L2: Status | M2: Asana Link
A3: 2025-08-02 | B3: Sat | C3: P_EM_2025_08_02_SF_D_PR_UGC_Wallpaper_Roundup | D3: Non-Sale | E3: Designed | G3: 2026-08-03 | H3: Mon | I3: POTM: Classic Kuba Cloth | J3: Non-Sale | K3: Batch & Blast | L3: Launched | M3: https://app.asana.com/1/5257710284167/project/1207522423363072/task/1216796972718529
A4: 2025-08-04 | B4: Mon | C4: P_EM_2025_08_04_SF_D_PR_RESEND_Bed_Print_Pairing | D4: Non-Sale | E4: Designed | G4: 2026-08-05 | H4: Wed | I4: Curtain Call | J4: Non-Sale | K4: Batch & Blast | L4: Launched | M4: https://app.asana.com/1/5257710284167/project/1207522423363072/task/1216797575342095
A5: 2025-08-06 | B5: Wed | C5: P_EM_2025_08_06_SF_D_PR_Fall_Preview_Launch | D5: Non-Sale | E5: Designed | G5: 2026-08-08 | H5: Sat | I5: The Curator's Choice | J5: Non-Sale | K5: Batch & Blast | L5: Launched | M5: https://app.asana.com/1/5257710284167/project/1207522423363072/task/1216797447641007
A6: 2025-08-07 | B6: Thu | C6: P_EM_2025_08_07_SF_D_PR_Sunset_Sale | D6: Sunset Sale | E6: Designed | G6: 2026-08-11 | H6: Tue | I6: Fall Preview | J6: Non-Sale | K6: Batch & Blast | L6: Launched | M6: https://app.asana.com/1/5257710284167/project/1207522423363072/task/1216815652805202
A7: 2025-08-08 | B7: Fri | C7: P_EM_2025_08_08_SF_D_PR_Treat_Yourself_Luxury | D7: Sunset Sale | E7: Designed | G7: 2026-08-13 | H7: Thu | I7: Swatch Push | J7: Non-Sale | K7: Batch & Blast | L7: Launched | M7: https://app.asana.com/1/5257710284167/project/1207522423363072/task/1216798013330835
A8: 2025-08-09 | B8: Sat | C8: P_EM_2025_08_09_SF_D_PR_Trend_Pattern_Drenching | D8: Sunset Sale | E8: Designed | G8: 2026-08-16 | H8: Sun | I8: MTO Furniture | J8: Non-Sale | K8: Batch & Blast | L8: Launched | M8: https://app.asana.com/1/5257710284167/project/1207522423363072/task/1216798014931359
A9: 2025-08-10 | B9: Sun | C9: P_EM_2025_08_10_SF_D_PR_Destination_Paris | D9: Sunset Sale | E9: Designed | G9: 2026-08-19 | H9: Wed | I9: Pillow Talk | J9: Non-Sale | K9: Batch & Blast | L9: Launched | M9: https://app.asana.com/1/5257710284167/project/1207522423363072/task/1216798308738886
A10: 2025-08-11 | B10: Mon | C10: P_EM_2025_08_11_SF_D_PR_New_Curtain_Patterns_Available | D10: Sunset Sale | E10: Designed | G10: 2026-08-20 | H10: Thu | I10: Labor Day Event Launch | J10: Labor Day Event | K10: Batch & Blast | L10: Launched | M10: https://app.asana.com/1/5257710284167/project/1207522423363072/task/1216797896393132
A11: 2025-08-12 | B11: Tue | C11: P_EM_2025_08_12_SF_D_PR_Guide_To_Bold_Interiors | D11: Sunset Sale | E11: Designed | G11: 2026-08-24 | H11: Mon | I11: The Throw Edit | J11: Labor Day Event | K11: Batch & Blast | L11: Launched | M11: https://app.asana.com/1/5257710284167/project/1207522423363072/task/1216798015841962
A12: 2025-08-13 | B12: Wed | C12: P_EM_2025_08_13_SF_D_PR_Sunset_Sale_Last_Chance | D12: Sunset Sale | E12: Designed | G12: 2026-08-26 | H12: Wed | I12: Wallpaper | J12: Labor Day Event | K12: Batch & Blast | L12: Launched | M12: https://app.asana.com/1/5257710284167/project/1207522423363072/task/1216798278920282
A13: 2025-08-16 | B13: Sat | C13: P_EM_2025_08_16_SF_D_PR_New_Neutrals | D13: Non-Sale | E13: Designed | G13: 2026-08-27 | H13: Thu | I13: Labor Day Event Reminder | J13: Labor Day Event | K13: Batch & Blast | L13: Launched | M13: https://app.asana.com/1/5257710284167/project/1207353785125835/task/1217027063157356
... A27: 2025-09-04 | B27: Thu | C27: P_EM_2025_09_04_PT_STF_PF_Labor_Day_Event_Ending_Soon_PM | D27: Labor Day Event | E27: Plain-Text | G27: 2026-09-30 | H27: Wed | I27: Pillows | J27: Non-Sale | K27: Batch & Blast | L27: Awaiting Creative | M27: https://app.asana.com/1/5257710284167/project/1207522423363072/task/1217618536111645
A28: 2025-09-04 | B28: Thu | C28: P_EM_2025_09_04_SF_D_PR_Labor_Day_Event_Last_Chance | D28: Labor Day Event | E28: Designed
A29: 2025-09-05 | B29: Fri | C29: P_EM_2025_09_05_SF_D_PR_Labor_Day_Event_Sale_Extension | D29: Labor Day Event (Extension) | E29: Designed
A30: 2025-09-06 | B30: Sat | C30: P_EM_2025_09_06_SF_D_PF_New_MTO_Furniture_Teaser | D30: Labor Day Event (Extension) | E30: Designed
A31: 2025-09-07 | B31: Sun | C31: P_EM_2025_09_07_SF_D_PR_Fall_Lookbook_Labor_Day_Event | D31: Labor Day Event (Extension) | E31: Designed
A32: 2025-09-08 | B32: Mon | C32: P_EM_2025_09_08_PT_STF_PF_Labor_Day_Event_Last_Chance_PM | D32: Labor Day Event (Extension) | E32: Plain-Text
A33: 2025-09-08 | B33: Mon | C33: P_EM_2025_09_08_SF_D_PR_Labor_Day_Event_Sale_Extension_Last_Chance | D33: Labor Day Event (Extension) | E33: Designed
A34: 2025-09-09 | B34: Tue | C34: P_EM_2025_09_09_SF_D_PF_New_MTO_Furniture_Launch_Studio | D34: Non-Sale | E34: Designed
A35: 2025-09-11 | B35: Thu | C35: P_EM_2025_09_11_SF_D_PF_New_York_Fashion_Week_Haute_Decor | D35: Non-Sale | E35: Designed
A36: 2025-09-12 | B36: Fri | C36: P_EM_2025_09_12_SF_D_PF_Studio_Furniture_Behind_the_Design | D36: Non-Sale | E36: Designed
A37: 2025-09-14 | B37: Sun | C37: P_EM_2025_09_14_SF_D_PF_Fall_Moodboard | D37: Non-Sale | E37: Designed
A38: 2025-09-15 | B38: Mon | C38: P_EM_2025_09_15_SF_D_PF_Fall_Trends | D38: Non-Sale | E38: Designed
A39: 2025-09-17 | B39: Wed | C39: P_EM_2025_09_17_SF_D_PF_Pillow_Play | D39: Non-Sale | E39: Designed
... A49: 2025-09-30 | B49: Tue | C49: P_EM_2025_09_30_SF_D_PF_Autumn_Sale_Last_Chance | D49: Autumn Event | E49: Designed

Sheet TI
A1: TI — 2025 (Aug 1 – Sep 30) | G1: TI — 2026 (Aug 1 – Sep 30, planned)
A2: Date | B2: Day | C2: Email Name | D2: Category | E2: Type | G2: Date | H2: Day | I2: Email Name | J2: Category | K2: Type | L2: Status | M2: Asana Link
A3: 2025-08-01 | B3: Fri | C3: P_EM_2025_08_01_TI_D_PF_New_England_Summer | D3: Non-Sale | E3: Designed | G3: 2026-08-03 | H3: Mon | I3: Last Chance: CW Stockwell Prints | J3: Non-Sale | K3: Batch & Blast | L3: QA Proof Sent | M3: https://app.asana.com/1/5257710284167/project/1207353785125835/task/1215605451707010
A4: 2025-08-02 | B4: Sat | C4: P_EM_2025_08_02_TI_D_PF_The_Dining_Edit | D4: Non-Sale | E4: Designed | G4: 2026-08-03 | H4: Mon | I4: Swatch Push | J4: Non-Sale | K4: Batch & Blast | L4: Launched | M4: https://app.asana.com/1/5257710284167/project/1207522423363072/task/1216400771821167
A5: 2025-08-04 | B5: Mon | C5: P_EM_2025_08_04_TI_D_PF_Central _Park_Toile_Launch | D5: Non-Sale | E5: Designed | G5: 2026-08-04 | H5: Tue | I5: Color Edit: Summer Blues | J5: Non-Sale | K5: Batch & Blast | L5: Launched | M5: https://app.asana.com/1/5257710284167/project/1207522423363072/task/1216400772253308
A6: 2025-08-06 | B6: Wed | C6: P_EM_2025_08_06_TI_D_PF_Fall_Preview_Updated | D6: Non-Sale | E6: Designed | G6: 2026-08-06 | H6: Thu | I6: Flash Sale Launch | J6: Flash Sale | K6: Batch & Blast | L6: QA Proof Sent | M6: https://app.asana.com/1/5257710284167/project/1207522423363072/task/1216415171446678
A7: 2025-08-07 | B7: Thu | C7: P_EM_2025_08_07_TI_D_PF_Sunset_Sale_Launch | D7: Sunset Sale | E7: Designed | G7: 2026-08-07 | H7: Fri | I7: Living Room Style Edit: Say It With a Sofa | J7: Flash Sale | K7: Batch & Blast | L7: QA Proof Sent | M7: https://app.asana.com/1/5257710284167/project/1207522423363072/task/1216400751924643
A8: 2025-08-08 | B8: Fri | C8: P_EM_2025_08_08_TI_D_POTM_Central_Park_Toile | D8: Sunset Sale | E8: Designed | G8: 2026-08-09 | H8: Sun | I8: Flash Sale Reminder | J8: Flash Sale | K8: Batch & Blast | L8: Launched | M8: https://app.asana.com/1/5257710284167/project/1207522423363072/task/1216400772229969
A9: 2025-08-09 | B9: Sat | C9: P_EM_2025_08_09_TI_D_PR_Walk_On_The_Wild_Side | D9: Sunset Sale | E9: Designed | G9: 2026-08-10 | H9: Mon | I9: Sunset Sale Reminder PM | J9: Flash Sale | K9: Plain-Text | L9: Launched | M9: https://app.asana.com/1/5257710284167/project/1207522423363072/task/1216400772253372
A10: 2025-08-10 | B10: Sun | C10: P_EM_2025_08_10_TI_D_PR_Kids_Edit | D10: Sunset Sale | E10: Designed | G10: 2026-08-11 | H10: Tue | I10: Flash Sale Last Chance | J10: Flash Sale | K10: Batch & Blast | L10: Launched | M10: https://app.asana.com/1/5257710284167/project/1207522423363072/task/1216400909353430
A11: 2025-08-11 | B11: Mon | C11: P_EM_2025_08_11_TI_D_PR_Destination_Capri_Postcard | D11: Sunset Sale | E11: Designed | G11: 2026-08-12 | H11: Wed | I11: Flash Sale Final Hours | J11: Flash Sale | K11: Batch & Blast | L11: Launched | M11: https://app.asana.com/1/5257710284167/project/1207522423363072/task/1216400944575844
A12: 2025-08-12 | B12: Tue | C12: P_EM_2025_08_12_TI_D_PR_Statement_Beds | D12: Sunset Sale | E12: Designed | G12: 2026-08-12 | H12: Wed | I12: Sunset Sale Final Hours PM | J12: Flash Sale | K12: Plain-Text | L12: Launched | M12: https://app.asana.com/1/5257710284167/project/1207522423363072/task/1216400944836298
A13: 2025-08-13 | B13: Wed | C13: P_EM_2025_08_13_TI_D_PF_Sunset_Sale_Last_Chance | D13: Sunset Sale | E13: Designed | G13: 2026-08-14 | H13: Fri | I13: Fall Preview | J13: Non-Sale | K13: Batch & Blast | L13: Launched | M13: https://app.asana.com/1/5257710284167/project/1207522423363072/task/1216400751492593
... A46: 2025-09-20 | B46: Sat | C46: P_EM_2025_09_20_TI_D_PF_Guest_Bedroom | D46: Fall Refresh / Fall Refresh Sale | E46: Designed | G46: 2026-09-30 | H46: Wed | I46: Flash Sale Last Chance | J46: Flash Sale | K46: Batch & Blast | L46: Awaiting Creative | M46: https://app.asana.com/1/5257710284167/project/1207353785125835/task/1217249748048459
A47: 2025-09-22 | B47: Mon | C47: P_EM_2025_09_22_TI_D_PF_Dragonfly_Inn | D47: Fall Refresh / Fall Refresh Sale | E47: Designed
A48: 2025-09-23 | B48: Tue | C48: P_EM_2025_09_23_TI_D_PF_Color_Edit_Color_Me_Cozy | D48: Fall Refresh / Fall Refresh Sale | E48: Designed
A49: 2025-09-24 | B49: Wed | C49: P_EM_2025_09_24_TI_D_PF_Fall_Refresh_Reminder | D49: Fall Refresh / Fall Refresh Sale | E49: Designed
A50: 2025-09-25 | B50: Thu | C50: P_EM_2025_09_25_TI_D_PF_UGC_Bedroom | D50: Fall Refresh / Fall Refresh Sale | E50: Designed
A51: 2025-09-27 | B51: Sat | C51: P_EM_2025_09_27_TI_D_PF_Destination_Cotswold_Escape | D51: Fall Refresh / Fall Refresh Sale | E51: Designed
A52: 2025-09-28 | B52: Sun | C52: P_EM_2025_09_28_TI_D_PF_Paris_Fashion_Week_Tres_Chic | D52: Fall Refresh / Fall Refresh Sale | E52: Designed
A53: 2025-09-29 | B53: Mon | C53: P_EM_2025_09_29_TI_D_PF_Sale_Home_Tour_Fall_at_the_Farmhouse | D53: Fall Refresh / Fall Refresh Sale | E53: Designed
A54: 2025-09-30 | B54: Tue | C54: P_EM_2025_09_30_TI_D_PF_Fall_Refresh_Sale_Last_Chance | D54: Fall Refresh / Fall Refresh Sale | E54: Designed

Sheet Pivot - Category x Year
A1: Category | B1: 2025 | C1: 2026 | D1: Total
A2: Labor Day Event | B2: =COUNTIFS('Data'!$F$2:$F$801,$A2,'Data'!$B$2:$B$801,2025) | C2: =COUNTIFS('Data'!$F$2:$F$801,$A2,'Data'!$B$2:$B$801,2026) | D2: =B2+C2
A3: Non-Sale | B3: =COUNTIFS('Data'!$F$2:$F$801,$A3,'Data'!$B$2:$B$801,2025) | C3: =COUNTIFS('Data'!$F$2:$F$801,$A3,'Data'!$B$2:$B$801,2026) | D3: =B3+C3
A4: Holiday-Ready Sale | B4: =COUNTIFS('Data'!$F$2:$F$801,$A4,'Data'!$B$2:$B$801,2025) | C4: =COUNTIFS('Data'!$F$2:$F$801,$A4,'Data'!$B$2:$B$801,2026) | D4: =B4+C4
A5: Flash Sale | B5: =COUNTIFS('Data'!$F$2:$F$801,$A5,'Data'!$B$2:$B$801,2025) | C5: =COUNTIFS('Data'!$F$2:$F$801,$A5,'Data'!$B$2:$B$801,2026) | D5: =B5+C5
A6: Labor Day Event (Extension) | B6: =COUNTIFS('Data'!$F$2:$F$801,$A6,'Data'!$B$2:$B$801,2025) | C6: =COUNTIFS('Data'!$F$2:$F$801,$A6,'Data'!$B$2:$B$801,2026) | D6: =B6+C6
A7: Warehouse Sale / Labor Day Event | B7: =COUNTIFS('Data'!$F$2:$F$801,$A7,'Data'!$B$2:$B$801,2025) | C7: =COUNTIFS('Data'!$F$2:$F$801,$A7,'Data'!$B$2:$B$801,2026) | D7: =B7+C7
A8: Sunset Sale / Sunset Sale / Flash Sale | B8: =COUNTIFS('Data'!$F$2:$F$801,$A8,'Data'!$B$2:$B$801,2025) | C8: =COUNTIFS('Data'!$F$2:$F$801,$A8,'Data'!$B$2:$B$801,2026) | D8: =B8+C8
A9: Autumn Event | B9: =COUNTIFS('Data'!$F$2:$F$801,$A9,'Data'!$B$2:$B$801,2025) | C9: =COUNTIFS('Data'!$F$2:$F$801,$A9,'Data'!$B$2:$B$801,2026) | D9: =B9+C9
A10: Sunset Sale | B10: =COUNTIFS('Data'!$F$2:$F$801,$A10,'Data'!$B$2:$B$801,2025) | C10: =COUNTIFS('Data'!$F$2:$F$801,$A10,'Data'!$B$2:$B$801,2026) | D10: =B10+C10
A11: Sunset Sale / Labor Day Event | B11: =COUNTIFS('Data'!$F$2:$F$801,$A11,'Data'!$B$2:$B$801,2025) | C11: =COUNTIFS('Data'!$F$2:$F$801,$A11,'Data'!$B$2:$B$801,2026) | D11: =B11+C11
A12: Weekend Flash Sale | B12: =COUNTIFS('Data'!$F$2:$F$801,$A12,'Data'!$B$2:$B$801,2025) | C12: =COUNTIFS('Data'!$F$2:$F$801,$A12,'Data'!$B$2:$B$801,2026) | D12: =B12+C12
A13: Labor Day Event / Labor Day Event (EA) | B13: =COUNTIFS('Data'!$F$2:$F$801,$A13,'Data'!$B$2:$B$801,2025) | C13: =COUNTIFS('Data'!$F$2:$F$801,$A13,'Data'!$B$2:$B$801,2026) | D13: =B13+C13
... A33: Labor Day (EA) | B33: =COUNTIFS('Data'!$F$2:$F$801,$A33,'Data'!$B$2:$B$801,2025) | C33: =COUNTIFS('Data'!$F$2:$F$801,$A33,'Data'!$B$2:$B$801,2026) | D33: =B33+C33
A34: Total | B34: =SUM(B2:B33) | C34: =SUM(C2:C33) | D34: =SUM(D2:D33)

Sheet Pivot - Brand x Year
A1: Brand | B1: 2025 | C1: 2026 | D1: Delta
A2: HAV | B2: =COUNTIFS('Data'!$A$2:$A$801,$A2,'Data'!$B$2:$B$801,2025) | C2: =COUNTIFS('Data'!$A$2:$A$801,$A2,'Data'!$B$2:$B$801,2026) | D2: =C2-B2
A3: CZ | B3: =COUNTIFS('Data'!$A$2:$A$801,$A3,'Data'!$B$2:$B$801,2025) | C3: =COUNTIFS('Data'!$A$2:$A$801,$A3,'Data'!$B$2:$B$801,2026) | D3: =C3-B3
A4: ID | B4: =COUNTIFS('Data'!$A$2:$A$801,$A4,'Data'!$B$2:$B$801,2025) | C4: =COUNTIFS('Data'!$A$2:$A$801,$A4,'Data'!$B$2:$B$801,2026) | D4: =C4-B4
A5: BUR | B5: =COUNTIFS('Data'!$A$2:$A$801,$A5,'Data'!$B$2:$B$801,2025) | C5: =COUNTIFS('Data'!$A$2:$A$801,$A5,'Data'!$B$2:$B$801,2026) | D5: =C5-B5
A6: STF | B6: =COUNTIFS('Data'!$A$2:$A$801,$A6,'Data'!$B$2:$B$801,2025) | C6: =COUNTIFS('Data'!$A$2:$A$801,$A6,'Data'!$B$2:$B$801,2026) | D6: =C6-B6
A7: TI | B7: =COUNTIFS('Data'!$A$2:$A$801,$A7,'Data'!$B$2:$B$801,2025) | C7: =COUNTIFS('Data'!$A$2:$A$801,$A7,'Data'!$B$2:$B$801,2026) | D7: =C7-B7
A8: Total | B8: =SUM(B2:B7) | C8: =SUM(C2:C7) | D8: =SUM(D2:D7)

Sheet Pivot - Brand x Category
A1: 2025
A2: Brand | B2: Labor Day Event | C2: Non-Sale | D2: Holiday-Ready Sale | E2: Labor Day Event (Extension) | F2: Sunset Sale / Sunset Sale / Flash Sale | G2: Autumn Event | H2: Sunset Sale | I2: Weekend Flash Sale | J2: Sunset Sale / Labor Day Event | K2: Fall Refresh / Fall Refresh Sale | L2: Labor Day Event / Labor Day Event (EA) | M2: Weekender Sale / Weekender Flash Sale | N2: Labor Day Event / Labor Day Event (Extension) | O2: Rug Event | P2: Bedroom Refresh Sale | Q2: HIP Private Sale / Guest-Ready Sale / Private Sale | R2: Subscriber Flash Sale - Lifecycle/Retail Only / VIP Flash Sale | S2: Labor Day Event (EA) | T2: Private Sale - Lifecycle/Retail Only / Private Sale | U2: Private Sale | V2: HIP Private Sale / Guest-Ready Sale / Holiday-Ready Sale / Private Sale | W2: Total
A3: HAV | B3: =COUNTIFS('Data'!$A$2:$A$801,$A3,'Data'!$F$2:$F$801,B$2,'Data'!$B$2:$B$801,2025) | C3: =COUNTIFS('Data'!$A$2:$A$801,$A3,'Data'!$F$2:$F$801,C$2,'Data'!$B$2:$B$801,2025) | D3: =COUNTIFS('Data'!$A$2:$A$801,$A3,'Data'!$F$2:$F$801,D$2,'Data'!$B$2:$B$801,2025) | E3: =COUNTIFS('Data'!$A$2:$A$801,$A3,'Data'!$F$2:$F$801,E$2,'Data'!$B$2:$B$801,2025) | F3: =COUNTIFS('Data'!$A$2:$A$801,$A3,'Data'!$F$2:$F$801,F$2,'Data'!$B$2:$B$801,2025) | G3: =COUNTIFS('Data'!$A$2:$A$801,$A3,'Data'!$F$2:$F$801,G$2,'Data'!$B$2:$B$801,2025) | H3: =COUNTIFS('Data'!$A$2:$A$801,$A3,'Data'!$F$2:$F$801,H$2,'Data'!$B$2:$B$801,2025) | I3: =COUNTIFS('Data'!$A$2:$A$801,$A3,'Data'!$F$2:$F$801,I$2,'Data'!$B$2:$B$801,2025) | ... V3: =COUNTIFS('Data'!$A$2:$A$801,$A3,'Data'!$F$2:$F$801,V$2,'Data'!$B$2:$B$801,2025) | W3: =SUM(B3:V3)
A4: CZ | B4: =COUNTIFS('Data'!$A$2:$A$801,$A4,'Data'!$F$2:$F$801,B$2,'Data'!$B$2:$B$801,2025) | C4: =COUNTIFS('Data'!$A$2:$A$801,$A4,'Data'!$F$2:$F$801,C$2,'Data'!$B$2:$B$801,2025) | D4: =COUNTIFS('Data'!$A$2:$A$801,$A4,'Data'!$F$2:$F$801,D$2,'Data'!$B$2:$B$801,2025) | E4: =COUNTIFS('Data'!$A$2:$A$801,$A4,'Data'!$F$2:$F$801,E$2,'Data'!$B$2:$B$801,2025) | F4: =COUNTIFS('Data'!$A$2:$A$801,$A4,'Data'!$F$2:$F$801,F$2,'Data'!$B$2:$B$801,2025) | G4: =COUNTIFS('Data'!$A$2:$A$801,$A4,'Data'!$F$2:$F$801,G$2,'Data'!$B$2:$B$801,2025) | H4: =COUNTIFS('Data'!$A$2:$A$801,$A4,'Data'!$F$2:$F$801,H$2,'Data'!$B$2:$B$801,2025) | I4: =COUNTIFS('Data'!$A$2:$A$801,$A4,'Data'!$F$2:$F$801,I$2,'Data'!$B$2:$B$801,2025) | ... V4: =COUNTIFS('Data'!$A$2:$A$801,$A4,'Data'!$F$2:$F$801,V$2,'Data'!$B$2:$B$801,2025) | W4: =SUM(B4:V4)
A5: ID | B5: =COUNTIFS('Data'!$A$2:$A$801,$A5,'Data'!$F$2:$F$801,B$2,'Data'!$B$2:$B$801,2025) | C5: =COUNTIFS('Data'!$A$2:$A$801,$A5,'Data'!$F$2:$F$801,C$2,'Data'!$B$2:$B$801,2025) | D5: =COUNTIFS('Data'!$A$2:$A$801,$A5,'Data'!$F$2:$F$801,D$2,'Data'!$B$2:$B$801,2025) | E5: =COUNTIFS('Data'!$A$2:$A$801,$A5,'Data'!$F$2:$F$801,E$2,'Data'!$B$2:$B$801,2025) | F5: =COUNTIFS('Data'!$A$2:$A$801,$A5,'Data'!$F$2:$F$801,F$2,'Data'!$B$2:$B$801,2025) | G5: =COUNTIFS('Data'!$A$2:$A$801,$A5,'Data'!$F$2:$F$801,G$2,'Data'!$B$2:$B$801,2025) | H5: =COUNTIFS('Data'!$A$2:$A$801,$A5,'Data'!$F$2:$F$801,H$2,'Data'!$B$2:$B$801,2025) | I5: =COUNTIFS('Data'!$A$2:$A$801,$A5,'Data'!$F$2:$F$801,I$2,'Data'!$B$2:$B$801,2025) | ... V5: =COUNTIFS('Data'!$A$2:$A$801,$A5,'Data'!$F$2:$F$801,V$2,'Data'!$B$2:$B$801,2025) | W5: =SUM(B5:V5)
A6: BUR | B6: =COUNTIFS('Data'!$A$2:$A$801,$A6,'Data'!$F$2:$F$801,B$2,'Data'!$B$2:$B$801,2025) | C6: =COUNTIFS('Data'!$A$2:$A$801,$A6,'Data'!$F$2:$F$801,C$2,'Data'!$B$2:$B$801,2025) | D6: =COUNTIFS('Data'!$A$2:$A$801,$A6,'Data'!$F$2:$F$801,D$2,'Data'!$B$2:$B$801,2025) | E6: =COUNTIFS('Data'!$A$2:$A$801,$A6,'Data'!$F$2:$F$801,E$2,'Data'!$B$2:$B$801,2025) | F6: =COUNTIFS('Data'!$A$2:$A$801,$A6,'Data'!$F$2:$F$801,F$2,'Data'!$B$2:$B$801,2025) | G6: =COUNTIFS('Data'!$A$2:$A$801,$A6,'Data'!$F$2:$F$801,G$2,'Data'!$B$2:$B$801,2025) | H6: =COUNTIFS('Data'!$A$2:$A$801,$A6,'Data'!$F$2:$F$801,H$2,'Data'!$B$2:$B$801,2025) | I6: =COUNTIFS('Data'!$A$2:$A$801,$A6,'Data'!$F$2:$F$801,I$2,'Data'!$B$2:$B$801,2025) | ... V6: =COUNTIFS('Data'!$A$2:$A$801,$A6,'Data'!$F$2:$F$801,V$2,'Data'!$B$2:$B$801,2025) | W6: =SUM(B6:V6)
A7: STF | B7: =COUNTIFS('Data'!$A$2:$A$801,$A7,'Data'!$F$2:$F$801,B$2,'Data'!$B$2:$B$801,2025) | C7: =COUNTIFS('Data'!$A$2:$A$801,$A7,'Data'!$F$2:$F$801,C$2,'Data'!$B$2:$B$801,2025) | D7: =COUNTIFS('Data'!$A$2:$A$801,$A7,'Data'!$F$2:$F$801,D$2,'Data'!$B$2:$B$801,2025) | E7: =COUNTIFS('Data'!$A$2:$A$801,$A7,'Data'!$F$2:$F$801,E$2,'Data'!$B$2:$B$801,2025) | F7: =COUNTIFS('Data'!$A$2:$A$801,$A7,'Data'!$F$2:$F$801,F$2,'Data'!$B$2:$B$801,2025) | G7: =COUNTIFS('Data'!$A$2:$A$801,$A7,'Data'!$F$2:$F$801,G$2,'Data'!$B$2:$B$801,2025) | H7: =COUNTIFS('Data'!$A$2:$A$801,$A7,'Data'!$F$2:$F$801,H$2,'Data'!$B$2:$B$801,2025) | I7: =COUNTIFS('Data'!$A$2:$A$801,$A7,'Data'!$F$2:$F$801,I$2,'Data'!$B$2:$B$801,2025) | ... V7: =COUNTIFS('Data'!$A$2:$A$801,$A7,'Data'!$F$2:$F$801,V$2,'Data'!$B$2:$B$801,2025) | W7: =SUM(B7:V7)
A8: TI | B8: =COUNTIFS('Data'!$A$2:$A$801,$A8,'Data'!$F$2:$F$801,B$2,'Data'!$B$2:$B$801,2025) | C8: =COUNTIFS('Data'!$A$2:$A$801,$A8,'Data'!$F$2:$F$801,C$2,'Data'!$B$2:$B$801,2025) | D8: =COUNTIFS('Data'!$A$2:$A$801,$A8,'Data'!$F$2:$F$801,D$2,'Data'!$B$2:$B$801,2025) | E8: =COUNTIFS('Data'!$A$2:$A$801,$A8,'Data'!$F$2:$F$801,E$2,'Data'!$B$2:$B$801,2025) | F8: =COUNTIFS('Data'!$A$2:$A$801,$A8,'Data'!$F$2:$F$801,F$2,'Data'!$B$2:$B$801,2025) | G8: =COUNTIFS('Data'!$A$2:$A$801,$A8,'Data'!$F$2:$F$801,G$2,'Data'!$B$2:$B$801,2025) | H8: =COUNTIFS('Data'!$A$2:$A$801,$A8,'Data'!$F$2:$F$801,H$2,'Data'!$B$2:$B$801,2025) | I8: =COUNTIFS('Data'!$A$2:$A$801,$A8,'Data'!$F$2:$F$801,I$2,'Data'!$B$2:$B$801,2025) | ... V8: =COUNTIFS('Data'!$A$2:$A$801,$A8,'Data'!$F$2:$F$801,V$2,'Data'!$B$2:$B$801,2025) | W8: =SUM(B8:V8)
A11: 2026
A12: Brand | B12: Labor Day Event | C12: Non-Sale | D12: Flash Sale | E12: Labor Day Event (Extension) | F12: Warehouse Sale / Labor Day Event | G12: Autumn Event | H12: Warehouse Sale / Labor Day (Extension) | I12: Flash Sale / Labor Day Event | J12: Labor Day (Extension) / Labor Day Event (Extension) | K12: Labor Day Event (EA) | L12: Warehouse Sale | M12: DE Backpocket Labor Day Preview | N12: Warehouse Sale / Labor Day Event (EA) | O12: Labor Day Event (EA) / Labor Day Event | P12: Flash Sale (Extension) | Q12: Labor Day (EA) | R12: Total
A13: HAV | B13: =COUNTIFS('Data'!$A$2:$A$801,$A13,'Data'!$F$2:$F$801,B$12,'Data'!$B$2:$B$801,2026) | C13: =COUNTIFS('Data'!$A$2:$A$801,$A13,'Data'!$F$2:$F$801,C$12,'Data'!$B$2:$B$801,2026) | D13: =COUNTIFS('Data'!$A$2:$A$801,$A13,'Data'!$F$2:$F$801,D$12,'Data'!$B$2:$B$801,2026) | E13: =COUNTIFS('Data'!$A$2:$A$801,$A13,'Data'!$F$2:$F$801,E$12,'Data'!$B$2:$B$801,2026) | F13: =COUNTIFS('Data'!$A$2:$A$801,$A13,'Data'!$F$2:$F$801,F$12,'Data'!$B$2:$B$801,2026) | G13: =COUNTIFS('Data'!$A$2:$A$801,$A13,'Data'!$F$2:$F$801,G$12,'Data'!$B$2:$B$801,2026) | H13: =COUNTIFS('Data'!$A$2:$A$801,$A13,'Data'!$F$2:$F$801,H$12,'Data'!$B$2:$B$801,2026) | I13: =COUNTIFS('Data'!$A$2:$A$801,$A13,'Data'!$F$2:$F$801,I$12,'Data'!$B$2:$B$801,2026) | ... Q13: =COUNTIFS('Data'!$A$2:$A$801,$A13,'Data'!$F$2:$F$801,Q$12,'Data'!$B$2:$B$801,2026) | R13: =SUM(B13:Q13)
A14: CZ | B14: =COUNTIFS('Data'!$A$2:$A$801,$A14,'Data'!$F$2:$F$801,B$12,'Data'!$B$2:$B$801,2026) | C14: =COUNTIFS('Data'!$A$2:$A$801,$A14,'Data'!$F$2:$F$801,C$12,'Data'!$B$2:$B$801,2026) | D14: =COUNTIFS('Data'!$A$2:$A$801,$A14,'Data'!$F$2:$F$801,D$12,'Data'!$B$2:$B$801,2026) | E14: =COUNTIFS('Data'!$A$2:$A$801,$A14,'Data'!$F$2:$F$801,E$12,'Data'!$B$2:$B$801,2026) | F14: =COUNTIFS('Data'!$A$2:$A$801,$A14,'Data'!$F$2:$F$801,F$12,'Data'!$B$2:$B$801,2026) | G14: =COUNTIFS('Data'!$A$2:$A$801,$A14,'Data'!$F$2:$F$801,G$12,'Data'!$B$2:$B$801,2026) | H14: =COUNTIFS('Data'!$A$2:$A$801,$A14,'Data'!$F$2:$F$801,H$12,'Data'!$B$2:$B$801,2026) | I14: =COUNTIFS('Data'!$A$2:$A$801,$A14,'Data'!$F$2:$F$801,I$12,'Data'!$B$2:$B$801,2026) | ... Q14: =COUNTIFS('Data'!$A$2:$A$801,$A14,'Data'!$F$2:$F$801,Q$12,'Data'!$B$2:$B$801,2026) | R14: =SUM(B14:Q14)
A15: ID | B15: =COUNTIFS('Data'!$A$2:$A$801,$A15,'Data'!$F$2:$F$801,B$12,'Data'!$B$2:$B$801,2026) | C15: =COUNTIFS('Data'!$A$2:$A$801,$A15,'Data'!$F$2:$F$801,C$12,'Data'!$B$2:$B$801,2026) | D15: =COUNTIFS('Data'!$A$2:$A$801,$A15,'Data'!$F$2:$F$801,D$12,'Data'!$B$2:$B$801,2026) | E15: =COUNTIFS('Data'!$A$2:$A$801,$A15,'Data'!$F$2:$F$801,E$12,'Data'!$B$2:$B$801,2026) | F15: =COUNTIFS('Data'!$A$2:$A$801,$A15,'Data'!$F$2:$F$801,F$12,'Data'!$B$2:$B$801,2026) | G15: =COUNTIFS('Data'!$A$2:$A$801,$A15,'Data'!$F$2:$F$801,G$12,'Data'!$B$2:$B$801,2026) | H15: =COUNTIFS('Data'!$A$2:$A$801,$A15,'Data'!$F$2:$F$801,H$12,'Data'!$B$2:$B$801,2026) | I15: =COUNTIFS('Data'!$A$2:$A$801,$A15,'Data'!$F$2:$F$801,I$12,'Data'!$B$2:$B$801,2026) | ... Q15: =COUNTIFS('Data'!$A$2:$A$801,$A15,'Data'!$F$2:$F$801,Q$12,'Data'!$B$2:$B$801,2026) | R15: =SUM(B15:Q15)
A16: BUR | B16: =COUNTIFS('Data'!$A$2:$A$801,$A16,'Data'!$F$2:$F$801,B$12,'Data'!$B$2:$B$801,2026) | C16: =COUNTIFS('Data'!$A$2:$A$801,$A16,'Data'!$F$2:$F$801,C$12,'Data'!$B$2:$B$801,2026) | D16: =COUNTIFS('Data'!$A$2:$A$801,$A16,'Data'!$F$2:$F$801,D$12,'Data'!$B$2:$B$801,2026) | E16: =COUNTIFS('Data'!$A$2:$A$801,$A16,'Data'!$F$2:$F$801,E$12,'Data'!$B$2:$B$801,2026) | F16: =COUNTIFS('Data'!$A$2:$A$801,$A16,'Data'!$F$2:$F$801,F$12,'Data'!$B$2:$B$801,2026) | G16: =COUNTIFS('Data'!$A$2:$A$801,$A16,'Data'!$F$2:$F$801,G$12,'Data'!$B$2:$B$801,2026) | H16: =COUNTIFS('Data'!$A$2:$A$801,$A16,'Data'!$F$2:$F$801,H$12,'Data'!$B$2:$B$801,2026) | I16: =COUNTIFS('Data'!$A$2:$A$801,$A16,'Data'!$F$2:$F$801,I$12,'Data'!$B$2:$B$801,2026) | ... Q16: =COUNTIFS('Data'!$A$2:$A$801,$A16,'Data'!$F$2:$F$801,Q$12,'Data'!$B$2:$B$801,2026) | R16: =SUM(B16:Q16)
A17: STF | B17: =COUNTIFS('Data'!$A$2:$A$801,$A17,'Data'!$F$2:$F$801,B$12,'Data'!$B$2:$B$801,2026) | C17: =COUNTIFS('Data'!$A$2:$A$801,$A17,'Data'!$F$2:$F$801,C$12,'Data'!$B$2:$B$801,2026) | D17: =COUNTIFS('Data'!$A$2:$A$801,$A17,'Data'!$F$2:$F$801,D$12,'Data'!$B$2:$B$801,2026) | E17: =COUNTIFS('Data'!$A$2:$A$801,$A17,'Data'!$F$2:$F$801,E$12,'Data'!$B$2:$B$801,2026) | F17: =COUNTIFS('Data'!$A$2:$A$801,$A17,'Data'!$F$2:$F$801,F$12,'Data'!$B$2:$B$801,2026) | G17: =COUNTIFS('Data'!$A$2:$A$801,$A17,'Data'!$F$2:$F$801,G$12,'Data'!$B$2:$B$801,2026) | H17: =COUNTIFS('Data'!$A$2:$A$801,$A17,'Data'!$F$2:$F$801,H$12,'Data'!$B$2:$B$801,2026) | I17: =COUNTIFS('Data'!$A$2:$A$801,$A17,'Data'!$F$2:$F$801,I$12,'Data'!$B$2:$B$801,2026) | ... Q17: =COUNTIFS('Data'!$A$2:$A$801,$A17,'Data'!$F$2:$F$801,Q$12,'Data'!$B$2:$B$801,2026) | R17: =SUM(B17:Q17)
A18: TI | B18: =COUNTIFS('Data'!$A$2:$A$801,$A18,'Data'!$F$2:$F$801,B$12,'Data'!$B$2:$B$801,2026) | C18: =COUNTIFS('Data'!$A$2:$A$801,$A18,'Data'!$F$2:$F$801,C$12,'Data'!$B$2:$B$801,2026) | D18: =COUNTIFS('Data'!$A$2:$A$801,$A18,'Data'!$F$2:$F$801,D$12,'Data'!$B$2:$B$801,2026) | E18: =COUNTIFS('Data'!$A$2:$A$801,$A18,'Data'!$F$2:$F$801,E$12,'Data'!$B$2:$B$801,2026) | F18: =COUNTIFS('Data'!$A$2:$A$801,$A18,'Data'!$F$2:$F$801,F$12,'Data'!$B$2:$B$801,2026) | G18: =COUNTIFS('Data'!$A$2:$A$801,$A18,'Data'!$F$2:$F$801,G$12,'Data'!$B$2:$B$801,2026) | H18: =COUNTIFS('Data'!$A$2:$A$801,$A18,'Data'!$F$2:$F$801,H$12,'Data'!$B$2:$B$801,2026) | I18: =COUNTIFS('Data'!$A$2:$A$801,$A18,'Data'!$F$2:$F$801,I$12,'Data'!$B$2:$B$801,2026) | ... Q18: =COUNTIFS('Data'!$A$2:$A$801,$A18,'Data'!$F$2:$F$801,Q$12,'Data'!$B$2:$B$801,2026) | R18: =SUM(B18:Q18)

Sheet Pivot - Type x Category
A1: 2025
A2: Category | B2: Batch & Blast | C2: Designed | D2: Plain-Text
A3: Labor Day Event | B3: =COUNTIFS('Data'!$F$2:$F$801,$A3,'Data'!$G$2:$G$801,B$2,'Data'!$B$2:$B$801,2025) | C3: =COUNTIFS('Data'!$F$2:$F$801,$A3,'Data'!$G$2:$G$801,C$2,'Data'!$B$2:$B$801,2025) | D3: =COUNTIFS('Data'!$F$2:$F$801,$A3,'Data'!$G$2:$G$801,D$2,'Data'!$B$2:$B$801,2025)
A4: Non-Sale | B4: =COUNTIFS('Data'!$F$2:$F$801,$A4,'Data'!$G$2:$G$801,B$2,'Data'!$B$2:$B$801,2025) | C4: =COUNTIFS('Data'!$F$2:$F$801,$A4,'Data'!$G$2:$G$801,C$2,'Data'!$B$2:$B$801,2025) | D4: =COUNTIFS('Data'!$F$2:$F$801,$A4,'Data'!$G$2:$G$801,D$2,'Data'!$B$2:$B$801,2025)
A5: Holiday-Ready Sale | B5: =COUNTIFS('Data'!$F$2:$F$801,$A5,'Data'!$G$2:$G$801,B$2,'Data'!$B$2:$B$801,2025) | C5: =COUNTIFS('Data'!$F$2:$F$801,$A5,'Data'!$G$2:$G$801,C$2,'Data'!$B$2:$B$801,2025) | D5: =COUNTIFS('Data'!$F$2:$F$801,$A5,'Data'!$G$2:$G$801,D$2,'Data'!$B$2:$B$801,2025)
A6: Labor Day Event (Extension) | B6: =COUNTIFS('Data'!$F$2:$F$801,$A6,'Data'!$G$2:$G$801,B$2,'Data'!$B$2:$B$801,2025) | C6: =COUNTIFS('Data'!$F$2:$F$801,$A6,'Data'!$G$2:$G$801,C$2,'Data'!$B$2:$B$801,2025) | D6: =COUNTIFS('Data'!$F$2:$F$801,$A6,'Data'!$G$2:$G$801,D$2,'Data'!$B$2:$B$801,2025)
A7: Sunset Sale / Sunset Sale / Flash Sale | B7: =COUNTIFS('Data'!$F$2:$F$801,$A7,'Data'!$G$2:$G$801,B$2,'Data'!$B$2:$B$801,2025) | C7: =COUNTIFS('Data'!$F$2:$F$801,$A7,'Data'!$G$2:$G$801,C$2,'Data'!$B$2:$B$801,2025) | D7: =COUNTIFS('Data'!$F$2:$F$801,$A7,'Data'!$G$2:$G$801,D$2,'Data'!$B$2:$B$801,2025)
